Workbook

Sheet Read me
A1: Supplementary Material
A2: Is It the Landfill? A Systematic Review of Methods for Attributing Groundwater Contamination to Landfill Leachate
A4: Contents
A5: Table S1. Reports sought for retrieval but not retrieved (n = 14).
A6: Table S2. Studies included in the review, with extracted data and appraisal scores (n = 133).
A7: Table S3. Reports excluded after assessment of the full text, with reasons (n = 48).
A8: Table S4. Thesaurus applied to the author keywords in the keyword co-occurrence analysis.
A9: Table S5. Sensitivity of the method profile and regional distribution to the definition of the subset.
A11: Method categories used in Table S2
A12: 1 Major ion hydrochemistry and facies analysis
A13: 2 Conservative tracers based on chloride and bromide
A14: 3 Nitrogen species and redox indicators
... A31: Summary (computed from the tables)
A32: Studies included | B32: =COUNTA('Table S2 Included'!A5:A137) -> 133
A33: Mean score (0 to 4) | B33: =ROUND(AVERAGE('Table S2 Included'!Q5:Q137),2) -> 2.56
A34: Studies meeting at least 3 of 4 criteria | B34: =COUNTIF('Table S2 Included'!R5:R137,"Yes") -> 76
A35: Reports not retrieved (Table S1) | B35: =COUNTA('Table S1 Not retrieved'!A5:A18) -> 14
A36: Reports excluded (Table S3) | B36: =COUNTA('Table S3 Excluded'!A5:A52) -> 48

Sheet Table S1 Not retrieved
A1: Table S1. Reports sought but not retrieved (n = 14)
A2: Full texts could not be obtained through institutional access, open access sources or requests to the authors.
A4: Record | B4: First author | C4: Year | D4: Title | E4: Journal | F4: DOI | G4: Reason not retrieved
A5: S1-1 | B5: Foley et al. | C5: 2012 | D5: Chlorofluorocarbons as tracers of landfill leachate in surface and groundwater | E5: Quarterly Journal of Engineering Geology and Hydrogeology | F5: 10.1144/1470-9236/10-044 | G5: No institutional access, no open access version, no copy from authors or repositories
A6: S1-2 | B6: Rusu et al. | C6: 2017 | D6: Assessment of groundwater and surface water contamination by landfill leachate: A case study in Neamt County, Romania | E6: Environmental Engineering and Management Journal | F6: 10.30638/eemj.2017.065 | G6: No institutional access, no open access version, no copy from authors or repositories
A7: S1-3 | B7: Stefania et al. | C7: 2019 | D7: The hydrochemical database TANGCHIM, a tool to manage groundwater quality data: the case study of a leachate plume from a dumping area | E7: Rendiconti Online Della Societa Geologica Italiana | F7: 10.3301/ROL.2019.21 | G7: Only the abstract available; no full text located
A8: S1-4 | B8: Kaur et al. | C8: 2022 | D8: Assessing the risk of landfill leachate on the groundwater quality of Chandigarh | E8: Journal of Environmental Biology | F8: 10.22438/jeb/43/4/MRN-2097 | G8: No institutional access, no open access version, no copy from authors or repositories
A9: S1-5 | B9: Zamani et al. | C9: 2022 | D9: Physicochemical Analysis of Leachates from the Public Landfill of Guercif City Before Restoration and Impact on the Tafrata Water Table, Soil, and River Moulouya in Morocco | E9: Tropical Journal of Natural Product Research | F9: 10.26538/tjnpr/v6i4.7 | G9: DOI does not resolve; no copy located
A10: S1-6 | B10: Patnaik et al. | C10: 2024 | D10: Monitoring groundwater quality using principal component analysis | E10: Applied Geomatics | F10: 10.1007/s12518-024-00552-z | G10: No institutional access, no open access version, no copy from authors or repositories
A11: S1-7 | B11: Majee et al. | C11: 2024 | D11: Isotopic tracing of leachate percolation from municipal solid waste dump sites to groundwater in diverse climatic zones of India | E11: Environmental Science and Pollution Research | F11: 10.1007/s11356-024-32551-3 | G11: No institutional access, no open access version, no copy from authors or repositories
A12: S1-8 | B12: Bhagwat et al. | C12: 2024 | D12: Use of environmental isotopes in leachate studies through multiple isotopic analysis–a review | E12: Environmental Technology Reviews | F12: 10.1080/21622515.2024.2315098 | G12: No institutional access, no open access version, no copy from authors or repositories
A13: S1-9 | B13: Tangahu et al. | C13: 2024 | D13: THE DISTRIBUTION OF LEACHATE POLLUTANTS FROM THE JABON LANDFILL, SIDOARJO REGENCY | E13: Journal of Solid Waste Technology and Management | F13: 10.5276/jswtm/iswmaw/502/2024.527 | G13: No institutional access, no open access version, no copy from authors or repositories
A14: S1-10 | B14: Nguyen et al. | C14: 2025 | D14: Exploring relationships among landfill leachate parameters through multivariate analysis for monitoring purposes | E14: Waste Management and Research | F14: 10.1177/0734242X241265062 | G14: No institutional access, no open access version, no copy from authors or repositories
A15: S1-11 | B15: Gupta et al. | C15: 2025 | D15: Spatio-temporal variation in hydrochemistry, environmental isotopes and its suitability for drinking and irrigation, National Capital Region, Delhi | E15: Environmental Earth Sciences | F15: 10.1007/s12665-025-12594-6 | G15: No institutional access, no open access version, no copy from authors or repositories
A16: S1-12 | B16: Hussain et al. | C16: 2025 | D16: Landfill leachate analysis from selected landfill sites and its impact on groundwater quality, New Delhi, India | E16: Environment, Development and Sustainability | F16: 10.1007/s10668-023-04403-6 | G16: No institutional access, no open access version, no copy from authors or repositories
... A18: S1-14 | B18: Venkatesh et al. | C18: 2026 | D18: Assessment of groundwater quality using water quality index, multivariate statistical analysis and machine learning techniques in the vicinity of an open dumping yard | E18: Environment, Development and Sustainability | F18: 10.1007/s10668-024-05209-w | G18: No institutional access, no open access version, no copy from authors or repositories

Sheet Table S2 Included
A1: Table S2. Studies included in the review (n = 133)
A2: Method categories and appraisal criteria are defined in "Read me". Ordered by year and first author.
A4: Study | B4: First author | C4: Year | D4: Title | E4: Journal | F4: DOI | G4: Source | H4: Country | I4: Region | J4: Aquifer type | K4: Method categories | L4: Isotopic tracers used | M4: Q1 | N4: Q2 | O4: Q3 | P4: Q4 | Q4: Score (0 to 4) | R4: Meets at least 3 of 4 | S4: Key finding on discrimination | T4: Site note
A5: S2-1 | B5: Canton et al. | C5: 2010 | D5: Impact of solid waste disposal on nutrient dynamics in a sandy catchment | E5: Journal Of Contaminant Hydrology | F5: 10.1016/j.jconhyd.2010.04.006 | G5: Scopus (abstract re-screening) | H5: France | I5: Europe | J5: Sandy coastal lowland aquifer | K5: 1, 3, 9, 10 | M5: 1 | N5: 1 | O5: 1 | P5: 1 | Q5: =SUM(M5:P5) -> 4 | R5: =IF(Q5>=3,"Yes","No") -> Yes | S5: Chloride plume about 1700 m but ammonium plume under 800 m in a sandy aquifer exfiltrating to a stream: nitrification and cation exchange attenuate ammonium; ERT and self-potential delineate the plume.
A6: S2-2 | B6: Rahim et al. | C6: 2010 | D6: Deterioration of groundwater quality in the vicinity of an active open-tipping site in West Malaysia | E6: Hydrogeology Journal | F6: 10.1007/s10040-009-0567-3 | G6: Web of Science search | H6: Malaysia | I6: East & South-East Asia | J6: Shallow (unprotected natural soil) | K6: 1, 4 | M6: 1 | N6: 1 | O6: 1 | P6: 1 | Q6: =SUM(M6:P6) -> 4 | R6: =IF(Q6>=3,"Yes","No") -> Yes | S6: Open-tipping site: 40 leachate and 36 groundwater samples against background bicarbonate water; ionic balance error of about 13.5% shows a leachate-dominated groundwater body under the site.
A7: S2-3 | B7: Alslaibi et al. | C7: 2011 | D7: Assessment of groundwater quality due to municipal solid waste landfills leachate | E7: Journal of Environmental Science and Technology | F7: 10.3923/jest.2011.419.436 | G7: Scopus search | H7: Palestine (Gaza) | I7: MENA | K7: 1, 3, 4 | M7: 0 | N7: 0 | O7: 1 | P7: 1 | Q7: =SUM(M7:P7) -> 2 | R7: =IF(Q7>=3,"Yes","No") -> No | S7: 18 downstream wells at a lined and an unlined landfill, with GIS maps of 1995–2008 data: Cl and EC highest close to the landfills along the south-westward flow; nitrate may also come from fertiliser and manure.
A8: S2-4 | B8: Cozzarelli et al. | C8: 2011 | D8: Biogeochemical evolution of a landfill leachate plume, Norman, Oklahoma | E8: Ground Water | F8: 10.1111/j.1745-6584.2010.00792.x | G8: Scopus search | H8: USA | I8: Americas | J8: Alluvial sand and gravel | K8: 1, 3, 6, 9 | M8: 1 | N8: 0 | O8: 1 | P8: 1 | Q8: =SUM(M8:P8) -> 3 | R8: =IF(Q8>=3,"Yes","No") -> Yes | S8: Decade-long redox zonation at the Norman Landfill: NH4 retarded by sorption and CH4 oxidised, both measured against conservative chloride; electron-acceptor capacity depleting.
A9: S2-5 | B9: Pearce et al. | C9: 2011 | D9: Subsurface characterization of groundwater contaminated by landfill leachate using microbial community profile data and a nonparametric decision-making process | E9: Water Resources Research | F9: 10.1029/2010WR009992 | G9: Scopus (abstract re-screening) | H9: USA | I9: Americas | K9: 7, 10 | M9: 1 | N9: 1 | O9: 0 | P9: 1 | Q9: =SUM(M9:P9) -> 3 | R9: =IF(Q9>=3,"Yes","No") -> Yes | S9: Microbial community profiles (T-RFLP), reduced by PCA and clustered with a weighted self-organising map, reproduce the background, fringe and contaminated zones defined by hydrochemistry at an unlined landfill.
A10: S2-6 | B10: Castañeda et al. | C10: 2012 | D10: Environmental isotopes and major ions for tracing leachate contamination from a municipal landfill in Metro Manila, Philippines | E10: Journal Of Environmental Radioactivity | F10: 10.1016/j.jenvrad.2012.01.022 | G10: Scopus search | H10: Philippines | I10: East & South-East Asia | K10: 1, 5, 6 | L10: Tritium | M10: 1 | N10: 1 | O10: 1 | P10: 1 | Q10: =SUM(M10:P10) -> 4 | R10: =IF(Q10>=3,"Yes","No") -> Yes | S10: Tritium is the confirmatory leachate tracer where conservative ions are obscured by geogenic and other sources; tritium and leachate ions decline exponentially with distance.
A11: S2-7 | B11: Lopes et al. | C11: 2012 | D11: Geophysical technique and groundwater monitoring to detect leachate contamination in the surrounding area of a landfill - Londrina (PR - Brazil) | E11: Journal Of Environmental Management | F11: 10.1016/j.jenvman.2012.05.028 | G11: Scopus search | H11: Brazil | I11: Americas | K11: 1, 4, 10 | M11: 1 | N11: 0 | O11: 0 | P11: 1 | Q11: =SUM(M11:P11) -> 2 | R11: =IF(Q11>=3,"Yes","No") -> No | S11: Surface resistivity defines the plume and guides well placement; highest EC and alkalinity fall in wells inside the resistivity anomaly.
A12: S2-8 | B12: Oufline et al. | C12: 2012 | D12: Impact of human activities on the physico-chemical quality of surface water and groundwater in the north of Marrakech (Morocco) | E12: Environmental Technology | F12: 10.1080/09593330.2012.660644 | G12: Scopus search | H12: Morocco | I12: MENA | K12: 1, 7 | M12: 1 | N12: 0 | O12: 0 | P12: 1 | Q12: =SUM(M12:P12) -> 2 | R12: =IF(Q12>=3,"Yes","No") -> No | S12: PCA with upstream/downstream points separates three sources in the Marrakech plain: landfill leachate, wastewater spreading and mining; wastewater and mining dominate.
A13: S2-9 | B13: Thomsen et al. | C13: 2012 | D13: Application of a contaminant mass balance method at an old landfill to assess the impact on water resources | E13: Waste Management | F13: 10.1016/j.wasman.2012.06.014 | G13: Scopus search | H13: Denmark | I13: Europe | J13: Clay till over limestone aquifer | K13: 3, 4, 9 | M13: 1 | N13: 0 | O13: 1 | P13: 1 | Q13: =SUM(M13:P13) -> 3 | R13: =IF(Q13>=3,"Yes","No") -> Yes | S13: Contaminant mass balance quantifies landfill discharge: chloride 9.4 t/yr, of which 1.4 t/yr reaches the limestone aquifer; works for Cl and DOC, less well for NH4 because of attenuation.
A14: S2-10 | B14: Haarstad and Mæhlum | C14: 2013 | D14: Tracing solid waste leachate in groundwater using δ13 C from dissolved inorganic carbon | E14: Isotopes in Environmental and Health Studies | F14: 10.1080/10256016.2012.668902 | G14: Scopus search | H14: Norway | I14: Europe | J14: Fractured bedrock and glaciofluvial deposits | K14: 5 | L14: δ13C, Tritium | M14: 1 | N14: 1 | O14: 1 | P14: 1 | Q14: =SUM(M14:P14) -> 4 | R14: =IF(Q14>=3,"Yes","No") -> Yes | S14: Across several landfills, only δ13C-DIC differs significantly between unpolluted, weakly and strongly polluted groundwater: more sensitive than organics, salts, nutrients or metals.
A15: S2-11 | B15: Han et al. | C15: 2013 | D15: Evaluation of organic contamination in urban groundwater surrounding a municipal landfill, Zhoukou, China | E15: Environmental Monitoring and Assessment | F15: 10.1007/s10661-012-2801-z | G15: Scopus (abstract re-screening) | H15: China | I15: East & South-East Asia | J15: Shallow aquifer | K15: 7, 10 | M15: 0 | N15: 1 | O15: 1 | P15: 1 | Q15: =SUM(M15:P15) -> 3 | R15: =IF(Q15>=3,"Yes","No") -> Yes | S15: PAH diagnostic ratios and PCA identify the landfill body as the main source of groundwater organic contamination, while wastewater and irrigation return flow explain surface-water pollution. | T15: Same landfill as study S2-15
A16: S2-12 | B16: Milosevic et al. | C16: 2013 | D16: Combined isotope and enantiomer analysis to assess the fate of phenoxy acids in a heterogeneous geologic setting at an old landfill | E16: Water Research | F16: 10.1016/j.watres.2012.10.029 | G16: Web of Science search | H16: Denmark | I16: Europe | J16: Clay till | K16: 2, 5, 6 | L16: δ13C | M16: 0 | N16: 1 | O16: 0 | P16: 1 | Q16: =SUM(M16:P16) -> 2 | R16: =IF(Q16>=3,"Yes","No") -> No | S16: Chloride and water isotopes as conservative tracers delineate two leachate flow paths in clay till; compound-specific and enantiomer-specific isotope analysis assess herbicide transformation at the Risby landfill. | T16: Same landfill as study S2-9
A17: S2-13 | B17: Raco et al. | C17: 2013 | D17: A quick and reliable method to detect and quantify contamination from MSW landfills: A case study | E17: Water, Air, and Soil Pollution | F17: 10.1007/s11270-012-1380-5 | G17: Scopus (abstract re-screening) | H17: Greece | I17: Europe | J17: Alluvial graben sediments | K17: 1, 5, 6, 10 | L17: δ13C, Tritium | M17: 0 | N17: 1 | O17: 1 | P17: 1 | Q17: =SUM(M17:P17) -> 3 | R17: =IF(Q17>=3,"Yes","No") -> Yes | S17: Leachate, boreholes and streams at two landfills with δD, δ18O, tritium, δ13C-DIC and landfill gas: chloride and metals are ambiguous leachate tracers in marine-derived sediments, where natural values mimic or mask contamination.
A18: S2-14 | B18: Fernández et al. | C18: 2014 | D18: Identification and assessment of water pollution as a consequence of a leachate plume migration from a municipal landfill site (Tucumán, Argentina) | E18: Environmental Geochemistry and Health | F18: 10.1007/s10653-013-9576-1 | G18: Scopus search | H18: Argentina | I18: Americas | J18: Alluvial (fluvial bar, paleochannel) | K18: 1, 3, 4 | M18: 1 | N18: 1 | O18: 1 | P18: 1 | Q18: =SUM(M18:P18) -> 4 | R18: =IF(Q18>=3,"Yes","No") -> Yes | S18: Redox zonation along the plume (SO4, NO3, Fe, Mn reduction); NH4, COD and HCO3 identify a second leachate source near P12; plume extends 900 m. Groundwater background value used.
A19: S2-15 | B19: Han et al. | C19: 2014 | D19: Evaluation of the impact of an uncontrolled landfill on surrounding groundwater quality, Zhoukou, China | E19: Journal of Geochemical Exploration | F19: 10.1016/j.gexplo.2013.09.008 | G19: Scopus search | H19: China | I19: East & South-East Asia | J19: Shallow aquifer (<30 m) | K19: 1, 3, 6, 7 | M19: 0 | N19: 1 | O19: 1 | P19: 1 | Q19: =SUM(M19:P19) -> 3 | R19: =IF(Q19>=3,"Yes","No") -> Yes | S19: PCA identifies TDS, Cl, NH4, Fe and Mn as leachate indicators and separates them from irrigation return flow dominating the shallow aquifer in summer; δ18O/δ2H show common recharge.
A20: S2-16 | B20: Hossain et al. | C20: 2014 | D20: Impact of landfill leachate on surface and ground water quality | E20: Journal of Environmental Science and Technology | F20: 10.3923/jest.2014.337.346 | G20: Scopus (abstract re-screening) | H20: Bangladesh | I20: South Asia | K20: 1, 4 | M20: 0 | N20: 0 | O20: 1 | P20: 0 | Q20: =SUM(M20:P20) -> 1 | R20: =IF(Q20>=3,"Yes","No") -> No | S20: Rowfabad landfill (Chittagong): leachate, surface water and three groundwater points within 300 m, assessed against drinking-water standards; faecal coliforms and iron in groundwater.
A21: S2-17 | B21: Moreau and Minard | C21: 2014 | D21: Coupled nitrogen and oxygen isotope study of nitrate at a rural unlined landfill in Western Victoria, Australia | E21: American Journal of Environmental Sciences | F21: 10.3844/ajessp.2014.383.390 | G21: Scopus search | H21: Australia | I21: Oceania | J21: Shallow unconfined with palaeochannels | K21: 3, 5 | L21: δ15N and δ18O of nitrate | M21: 1 | N21: 1 | O21: 0 | P21: 1 | Q21: =SUM(M21:P21) -> 3 | R21: =IF(Q21>=3,"Yes","No") -> Yes | S21: Nitrate dual isotopes separate leachate-derived nitrate with denitrification downgradient from agricultural nitrate upgradient at a rural unlined landfill.
A22: S2-18 | B22: Syafalni et al. | C22: 2014 | D22: Isotopic and hydrochemistry fingerprinting of leachate migration in shallow groundwater at controlled and uncontrolled landfill sites | E22: World Applied Sciences Journal | F22: 10.5829/idosi.wasj.2014.31.06.217 | G22: Scopus search | H22: Malaysia | I22: East & South-East Asia | J22: Shallow groundwater | K22: 1, 6 | M22: 0 | N22: 1 | O22: 1 | P22: 1 | Q22: =SUM(M22:P22) -> 3 | R22: =IF(Q22>=3,"Yes","No") -> Yes | S22: Piper facies and δ2H/δ18O at a controlled and an uncontrolled landfill: enriched δ2H and δ18O shift mark leachate mixing in specific boreholes.
A23: S2-19 | B23: Abd El-Salam and Abu-Zuid | C23: 2015 | D23: Impact of landfill leachate on the groundwater quality: A case study in Egypt | E23: Journal Of Advanced Research | F23: 10.1016/j.jare.2014.02.003 | G23: Scopus search | H23: Egypt | I23: MENA | K23: 1, 4 | M23: 0 | N23: 0 | O23: 1 | P23: 0 | Q23: =SUM(M23:P23) -> 1 | R23: =IF(Q23>=3,"Yes","No") -> No | S23: Alexandria landfills: biodegradable, un-stabilised leachate (BOD5/COD 0.69), but groundwater near the lined cells not severely contaminated.
A24: S2-20 | B24: Atta et al. | C24: 2015 | D24: The potential impact of leachate-contaminated groundwater of an ex-landfill site at Taman Beringin Kuala Lumpur, Malaysia | E24: Environmental Earth Sciences | F24: 10.1007/s12665-014-3675-x | G24: Scopus (abstract re-screening) | H24: Malaysia | I24: East & South-East Asia | K24: 1, 4 | M24: 1 | N24: 1 | O24: 1 | P24: 1 | Q24: =SUM(M24:P24) -> 4 | R24: =IF(Q24>=3,"Yes","No") -> Yes | S24: Taman Beringin ex-landfill: four monitoring wells including an upstream one and six leachate points; COD, BOD, NH3-N, Cl, F and metals exceed standards downgradient.
A25: S2-21 | B25: Aziz and Maulood | C25: 2015 | D25: Contamination valuation of soil and groundwater source at anaerobic municipal solid waste landfill site | E25: Environmental Monitoring And Assessment | F25: 10.1007/s10661-015-4971-y | G25: Scopus (abstract re-screening) | H25: Iraq | I25: MENA | J25: Unconfined and leaky unconfined (conglomerate) | K25: 1, 4 | M25: 1 | N25: 0 | O25: 1 | P25: 1 | Q25: =SUM(M25:P25) -> 3 | R25: =IF(Q25>=3,"Yes","No") -> Yes | S25: Erbil landfill: leachate, soil and groundwater compared with unpolluted groundwater outside the landfill; leachate in the acid phase.
A26: S2-22 | B26: Graham et al. | C26: 2015 | D26: Field Measurement of Fluorescent Dissolved Organic Material as a Means of Early Detection of Leachate Plumes | E26: Water, Air, and Soil Pollution | F26: 10.1007/s11270-015-2475-6 | G26: Scopus search | H26: Australia | I26: Oceania | J26: Fractured rock | K26: 4, 9, 10 | M26: 1 | N26: 1 | O26: 1 | P26: 1 | Q26: =SUM(M26:P26) -> 4 | R26: =IF(Q26>=3,"Yes","No") -> Yes | S26: In-situ FDOM detects leachate at up to 98% dilution where major ions show no impact above background; photodegradable fluorescent whitening agents confirm the leachate origin.
A27: S2-23 | B27: He et al. | C27: 2015 | D27: Using fluorescence spectroscopy coupled with chemometric analysis to investigate the origin, composition, and dynamics of dissolved organic matter in leachate-polluted groundwater | E27: Environmental Science And Pollution Research | F27: 10.1007/s11356-014-4029-7 | G27: Scopus (abstract re-screening) | H27: China | I27: East & South-East Asia | K27: 4, 7, 10 | M27: 1 | N27: 0 | O27: 1 | P27: 1 | Q27: =SUM(M27:P27) -> 3 | R27: =IF(Q27>=3,"Yes","No") -> Yes | S27: EEM-PARAFAC with PCA separates upstream from downstream groundwater at a Beijing dumpsite; leachate raises the protein-like (microbial) DOM component.
A28: S2-24 | B28: Markic et al. | C28: 2015 | D28: ASSESSMENT OF THE IMPACT OF BANJALUKA LANDFILL ON GROUNDWATER QUALITY | E28: Carpathian Journal Of Earth And Environmental Sciences | G28: Web of Science search | H28: Bosnia and Herzegovina | I28: Europe | J28: Shallow (piezometers at 8 m) | K28: 1, 7 | M28: 1 | N28: 0 | O28: 1 | P28: 1 | Q28: =SUM(M28:P28) -> 3 | R28: =IF(Q28>=3,"Yes","No") -> Yes | S28: Banjaluka landfill: PCA of three piezometers and monthly leachate separates sites by pollution level; the piezometer outside the landfill influence clusters apart.
A29: S2-25 | B29: Porowska | C29: 2015 | D29: Determination of the origin of dissolved inorganic carbon in groundwater around a reclaimed landfill in Otwock using stable carbon isotopes | E29: Waste Management | F29: 10.1016/j.wasman.2015.01.044 | G29: Scopus search | H29: Poland | I29: Europe | K29: 5, 9 | L29: δ13C | M29: 1 | N29: 1 | O29: 0 | P29: 1 | Q29: =SUM(M29:P29) -> 3 | R29: =IF(Q29>=3,"Yes","No") -> Yes | S29: Keeling plot and two-component mixing separate DIC from aquifer organic matter and carbonate dissolution (background) from landfill organic-matter biodegradation (contaminated).
A30: S2-26 | B30: Wijesekara et al. | C30: 2015 | D30: Leachate plume delineation and lithologic profiling using surface resistivity in an open municipal solid waste dumpsite, Sri Lanka | E30: Environmental Technology | F30: 10.1080/09593330.2014.963697 | G30: Scopus search | H30: Sri Lanka | I30: South Asia | J30: Shallow/perched over bedrock at 3–5 m | K30: 10 | M30: 0 | N30: 0 | O30: 1 | P30: 1 | Q30: =SUM(M30:P30) -> 2 | R30: =IF(Q30>=3,"Yes","No") -> No | S30: 1D and 2D resistivity delineate the leachate plume and its flow toward the Mahaweli River; used to site permeable reactive barriers.
A31: S2-27 | B31: He and Fan | C31: 2016 | D31: Investigating the effect of landfill leachates on the characteristics of dissolved organic matter in groundwater using excitation–emission matrix fluorescence spectra coupled with fluorescence regional integration and self-organizing map | E31: Environmental Science And Pollution Research | F31: 10.1007/s11356-016-7308-7 | G31: Scopus (abstract re-screening) | H31: China | I31: East & South-East Asia | K31: 4, 7, 10 | M31: 1 | N31: 0 | O31: 1 | P31: 1 | Q31: =SUM(M31:P31) -> 3 | R31: =IF(Q31>=3,"Yes","No") -> Yes | S31: EEM with fluorescence regional integration and SOM: groundwater in the landfill matches the leachate fluorescence; fulvic-like matter decreases and protein-like matter increases with leachate pollution. | T31: Same landfill as study S2-23
A32: S2-28 | B32: Koda et al. | C32: 2016 | D32: Ammonium Concentration and Migration in Groundwater in the Vicinity of Waste Management Site Located in the Neighborhood of Protected Areas of Warsaw, Poland | E32: Sustainability | F32: 10.3390/su8121253 | G32: Web of Science search | H32: Poland | I32: Europe | K32: 1, 3 | M32: 0 | N32: 0 | O32: 0 | P32: 0 | Q32: =SUM(M32:P32) -> 0 | R32: =IF(Q32>=3,"Yes","No") -> No | S32: Radiowo landfill: ammonium in piezometers over two decades and the effect of a bentonite cut-off wall; neighbouring industrial and urban sources described as context only.
A33: S2-29 | B33: Lu et al. | C33: 2016 | D33: Assessment of major ions and heavy metals in groundwater: a case study from Guangzhou and Zhuhai of the Pearl River Delta, China | E33: Frontiers Of Earth Science | F33: 10.1007/s11707-015-0513-8 | G33: Scopus search | H33: China | I33: East & South-East Asia | J33: Regional (Pearl River Delta; basement weathering, seawater mixing) | K33: 1, 6 | M33: 0 | N33: 0 | O33: 0 | P33: 1 | Q33: =SUM(M33:P33) -> 1 | R33: =IF(Q33>=3,"Yes","No") -> No | S33: Regional study attributing Pb, As and Mn to landfill leachate and Cd to leachate plus agriculture, alongside mining and industrial sources.
A34: S2-30 | B34: Mangimbulude et al. | C34: 2016 | D34: Hydrochemical characterization of a tropical, coastal aquifer affected by landfill leachate and seawater intrusion | E34: Asian Journal Of Water Environment And Pollution | F34: 10.3233/AJW-160038 | G34: Scopus search | H34: Indonesia | I34: East & South-East Asia | J34: Coastal aquifer (seawater intrusion) | K34: 1, 2, 3, 4, 9 | M34: 1 | N34: 0 | O34: 1 | P34: 1 | Q34: =SUM(M34:P34) -> 3 | R34: =IF(Q34>=3,"Yes","No") -> Yes | S34: Separates seawater intrusion from leachate influence using Cl/SO4 and a conservative Cl mixing fraction against reference wells; landfill signal carried by NH4, COD, HCO3, Fe2+.
A35: S2-31 | B35: Porowska | C35: 2016 | D35: Assessment of a degree of geochemical maturation and activity of a closed landfill site in Poland | E35: Environmental Earth Sciences | F35: 10.1007/s12665-016-5256-7 | G35: Scopus (abstract re-screening) | H35: Poland | I35: Europe | K35: 4, 5 | L35: δ13C | M35: 1 | N35: 1 | O35: 0 | P35: 1 | Q35: =SUM(M35:P35) -> 3 | R35: =IF(Q35>=3,"Yes","No") -> Yes | S35: δ13C-DIC and BOD/COD of leachate-contaminated groundwater place the Otwock landfill between methanogenic and air-intrusion phases, still active 24 years after closure. | T35: Same landfill as study S2-25
A36: S2-32 | B36: Sanci and Panarello | C36: 2016 | D36: Carbon stable isotopes as indicators of the origin and evolution of CO2 and CH4 in urban solid waste disposal sites and nearby areas | E36: Environmental Earth Sciences | F36: 10.1007/s12665-015-4906-5 | G36: Web of Science search | H36: Argentina | I36: Americas | K36: 5, 6 | L36: δ13C | M36: 0 | N36: 1 | O36: 0 | P36: 1 | Q36: =SUM(M36:P36) -> 2 | R36: =IF(Q36>=3,"Yes","No") -> No | S36: δ13C and δ2H of CH4 and CO2 in soil gas and groundwater: rising DIC and δ13C-DIC enrichment (up to +4‰) record methanogenic carbon transported into the aquifer. | T36: Same landfill as study S2-33
A37: S2-33 | B37: Sanci et al. | C37: 2016 | D37: Hydrogeochemistry and stable isotopes of a solid waste disposal area from gualeguaychú, entreríos, Argentina | E37: Journal of Solid Waste Technology and Management | F37: 10.5276/JSWTM.2016.71 | G37: Scopus search | H37: Argentina | I37: Americas | J37: Unconfined aquifer (loess/alluvial plain) | K37: 1, 5, 6, 9 | L37: δ13C | M37: 1 | N37: 0 | O37: 1 | P37: 1 | Q37: =SUM(M37:P37) -> 3 | R37: =IF(Q37>=3,"Yes","No") -> Yes | S37: Geochemical mixing models of pristine water and leachate, with δ18O/δ2H, δ13C-DIC and δ13C-DOC, separate leachate from evaporation and marine ingression.
A38: S2-34 | B38: De et al. | C38: 2017 | D38: Appraisal of seasonal variation of groundwater quality near an uncontrolled municipal solid waste landfill in Kolkata, India | E38: Global Nest Journal | F38: 10.30955/gnj.002172 | G38: Scopus search | H38: India | I38: South Asia | K38: 1, 7 | M38: 1 | N38: 1 | O38: 1 | P38: 1 | Q38: =SUM(M38:P38) -> 4 | R38: =IF(Q38>=3,"Yes","No") -> Yes | S38: Dhapa landfill (Kolkata): HCA separates near-landfill samples from upstream samples in both seasons; Na–Cl facies closest to the site; reducing conditions near the landfill.
A39: S2-35 | B39: Ling and Zhang | C39: 2017 | D39: Evaluation of surface water and groundwater contamination in a MSW landfill area using hydrochemical analysis and electrical resistivity tomography: a case study in Sichuan province, Southwest China | E39: Environmental Monitoring and Assessment | F39: 10.1007/s10661-017-5832-7 | G39: Scopus search | H39: China | I39: East & South-East Asia | J39: Loose valley sediments | K39: 1, 4, 10 | M39: 1 | N39: 0 | O39: 1 | P39: 1 | Q39: =SUM(M39:P39) -> 3 | R39: =IF(Q39>=3,"Yes","No") -> Yes | S39: Leachate water pollution index against upstream background wells, with three ERT profiles and laboratory resistivity calibration; groundwater deteriorated up to 500 m downstream.
A40: S2-36 | B40: Maurya et al. | C40: 2017 | D40: Detailed landfill leachate plume mapping using 2D and 3D electrical resistivity tomography - with correlation to ionic strength measured in screens | E40: Journal Of Applied Geophysics | F40: 10.1016/j.jappgeo.2017.01.019 | G40: Web of Science search | H40: Denmark | I40: Europe | K40: 10 | M40: 0 | N40: 0 | O40: 0 | P40: 1 | Q40: =SUM(M40:P40) -> 1 | R40: =IF(Q40>=3,"Yes","No") -> No | S40: 2D and 3D ERT map the leachate plume of the unlined Grindsted landfill along and across the flow direction, correlated with ionic strength in well screens.
A41: S2-37 | B41: Moreira et al. | C41: 2017 | D41: DC resistivity investigation in a fractured aquifer system contaminated by leachate from an old dump | E41: Geofisica Internacional | G41: Web of Science search | H41: Brazil | I41: Americas | J41: Fractured granite | K41: 1, 10 | M41: 0 | N41: 1 | O41: 0 | P41: 1 | Q41: =SUM(M41:P41) -> 2 | R41: =IF(Q41>=3,"Yes","No") -> No | S41: 2D and 3D DC resistivity integrated with groundwater chemistry map leachate in a fractured aquifer beneath a dump closed in 2004.
...

Sheet Table S3 Excluded
A1: Table S3. Reports excluded after assessment of the full text, with reasons (n = 48)
A2: Ordered by reason category, then by year.
A4: Record | B4: First author | C4: Year | D4: Title | E4: Journal | F4: DOI | G4: Reason category | H4: Specific reason
A5: S3-1 | B5: Lotram et al. | C5: 2011 | D5: Contributions of the physico-chemical waste characterization for the study of the transfer of pollutants from a former urban landfill | E5: Techniques - Sciences - Methodes | F5: 10.1051/tsm/201110062 | G5: Full text not in English | H5: Full text in French
A6: S3-2 | B6: Azari et al. | C6: 2023 | D6: Influence of the Babolsar landfill leachate on groundwater quality | E6: Kharazmi Journal of Earth Sciences | F6: 10.22034/KJES.2023.9.1.106451 | G6: Full text not in English | H6: Full text in Persian
A7: S3-3 | B7: Cholcheh et al. | C7: 2025 | D7: Assessment of landfill and municipal wastewater impact on groundwater in the aquifer of Hamzeh city, northeast of Dezful, using the self-organizing map method | E7: Kharazmi Journal of Earth Sciences | F7: 10.22034/KJES.2025.11.2.108241 | G7: Full text not in English | H7: Full text in Persian
A8: S3-4 | B8: Katz et al. | C8: 2011 | D8: Using Cl/Br ratios and other indicators to assess potential impacts on groundwater quality from septic systems: A review and examples from principal aquifers in the United States | E8: Journal of Hydrology | F8: 10.1016/j.jhydrol.2010.11.017 | G8: Secondary literature (review) | H8: Secondary literature (review)
A9: S3-5 | B9: Han et al. | C9: 2016 | D9: A review of groundwater contamination near municipal solid waste landfill sites in China | E9: Science of the Total Environment | F9: 10.1016/j.scitotenv.2016.06.201 | G9: Secondary literature (review) | H9: Secondary literature (review)
A10: S3-6 | B10: Sankoh et al. | C10: 2022 | D10: A review on the application of isotopic techniques to trace groundwater pollution sources within developing countries | E10: Water (Switzerland) | F10: 10.3390/w14010035 | G10: Secondary literature (review) | H10: Secondary literature (review)
A11: S3-7 | B11: Gunarathne et al. | C11: 2024 | D11: Environmental pitfalls and associated human health risks and ecological impacts from landfill leachate contaminants: Current evidence, recommended interventions and future directions | E11: Science of the Total Environment | F11: 10.1016/j.scitotenv.2023.169026 | G11: Secondary literature (review) | H11: Secondary literature (review of leachate composition and risks)
A12: S3-8 | B12: Porowska | C12: 2024 | D12: Carbon and Sulfur Isotope Methods for Tracing Groundwater Contamination: A Review of Sustainable Utilization in Reclaimed Municipal Landfill Areas | E12: Sustainability (Switzerland) | F12: 10.3390/su16114507 | G12: Secondary literature (review) | H12: Secondary literature (review)
A13: S3-9 | B13: Oubeid et al. | C13: 2025 | D13: Global applications of stable isotopes for identifying nitrate pollution sources in groundwater: a comprehensive review | E13: Frontiers in Water | F13: 10.3389/frwa.2025.1666498 | G13: Secondary literature (review) | H13: Secondary literature (review)
A14: S3-10 | B14: Ford et al. | C14: 2011 | D14: Delineating landfill leachate discharge to an arsenic contaminated waterway | E14: Chemosphere | F14: 10.1016/j.chemosphere.2011.09.046 | G14: Not a municipal solid waste landfill | H14: Not a municipal solid waste landfill (military-base solid waste, incinerator ash and munitions; Superfund site)
A15: S3-11 | B15: Harte et al. | C15: 2012 | D15: Heterogeneous redox conditions, arsenic mobility, and groundwater flow in a fractured-rock aquifer near a waste repository site in New Hampshire, USA | E15: Hydrogeology Journal | F15: 10.1007/s10040-012-0844-4 | G15: Not a municipal solid waste landfill | H15: Hazardous-waste Superfund site, not MSW landfill; arsenic mobility focus
A16: S3-12 | B16: Kaown et al. | C16: 2015 | D16: Hydrogeochemical and microbial characteristics in aquifers contaminated with leachate from animal carcass disposal sites | E16: Environmental Earth Sciences | F16: 10.1007/s12665-014-3750-3 | G16: Not a municipal solid waste landfill | H16: Not MSW landfill leachate (animal carcass burial pits); microbial community focus
... A52: S3-48 | B52: Vaishna et al. | C52: 2025 | D52: Investigating combustion derived runoff from solid waste dumpyard fire suppression activities: chemical profile and environmental risks | E52: Environmental Science: Processes and Impacts | F52: 10.1039/d5em00343a | G52: No method linking groundwater composition to leachate | H52: No method linking groundwater composition to leachate (combustion-derived runoff from a dump fire)

Sheet Table S4 Thesaurus
A1: Table S4. Thesaurus applied to the keywords in the keyword co-occurrence analysis (Supplementary Figure S1)
A2: Keywords in the first column were replaced by the term in the second column. An empty second column means the keyword was removed: search terms, generic terms and terms describing the assessment of water quality and health risk.
A4: Keyword as found | B4: Replaced by
A5: water chemistry | B5: hydrogeochemistry
A6: heavy metal contamination | B6: heavy metals
A7: stable carbon isotopes | B7: carbon isotopes
A8: nitrate contamination | B8: nitrate
A9: groundwater contamination | B9: (removed)
A10: landfill leachate | B10: (removed)
A11: municipal solid waste landfill | B11: (removed)
A12: groundwater quality | B12: (removed)
A13: water quality index | B13: (removed)
A14: manganese | B14: (removed)
A15: lead | B15: (removed)
... A38: water pollution | B38: (removed)

Sheet Table S5 Sensitivity
A1: Table S5. Sensitivity of the method profile and regional distribution to the definition of the subset
A2: Percentages of studies in each subset. Scores are on the four-criterion appraisal (0 to 4). The upper tertile of the score distribution corresponds to a score of 3 or more.
A4: Subset | B4: n | C4: Major ions % | D4: Multivariate % | E4: Isotopic tracers % | F4: Water isotopes % | G4: Mixing % | H4: Geophysics % | I4: ≥3 categories % | J4: MENA+SSA %
A5: All studies | B5: 133 | C5: 74 | D5: 35 | E5: 22 | F5: 19 | G5: 16 | H5: 19 | I5: 49 | J5: 27
A6: ≥2 of 4 | B6: 111 | C6: 72 | D6: 37 | E6: 26 | F6: 21 | G6: 19 | H6: 18 | I6: 54 | J6: 23
A7: ≥3 of 4 (main) | B7: 76 | C7: 68 | D7: 41 | E7: 32 | F7: 26 | G7: 21 | H7: 16 | I7: 62 | J7: 18
A8: All 4 of 4 | B8: 24 | C8: 62 | D8: 38 | E8: 38 | F8: 25 | G8: 25 | H8: 29 | I8: 71 | J8: 0
A9: Upper tertile | B9: 76 | C9: 68 | D9: 41 | E9: 32 | F9: 26 | G9: 21 | H9: 16 | I9: 62 | J9: 18
A10: Background point (Q2) | B10: 70 | C10: 67 | D10: 36 | E10: 29 | F10: 20 | G10: 21 | H10: 21 | I10: 59 | J10: 17
A11: Leachate sampled (Q4) | B11: 87 | C11: 75 | D11: 39 | E11: 23 | F11: 20 | G11: 20 | H11: 14 | I11: 62 | J11: 26
